Workbook

Sheet Catalogo_BR
A1: id | B1: Titulo_BR | C1: Titulo_Original | D1: Codigo_TecToy | E1: Ano | F1: Variante | G1: Edicao | H1: Genero | I1: Sub-Genero | J1: Peripherals | K1: Players | L1: Tamanho | M1: Desenvolvedor | N1: Distribuidor | O1: FM | P1: Observacao | Q1: Exclusivo_BR
A2: BR-245-CU | B2: 20 em 1 | E2: 1999 | G2: CU | O2: FALSE
A3: BR-001-GG | B3: Ace of Aces | E3: 1991 | G3: GG | H3: Shooting | I3: Nave | O3: FALSE
A4: BR-002-GG | B4: Action Fighter | E4: 1986 | G4: GG | H4: Action | O4: FALSE
A5: BR-003-GG | B5: Aerial Assault | E5: 1990 | G5: GG | H5: Shooting | I5: Nave | O5: FALSE
A6: BR-004-CP | B6: After Burner | E6: 1987 | G6: CP | H6: Shooting | O6: FALSE
A7: BR-004-GG | B7: After Burner | E7: 1987 | G7: GG | H7: Shooting | O7: FALSE | P7: [Verificar ano da edição]
A8: BR-005-GG | B8: Air Rescue | E8: 1992 | G8: GG | H8: Shooting | O8: FALSE
A9: BR-006-GG | B9: Alex Kidd High-Tech World | E9: 1989 | G9: GG | H9: RPG | I9: RPG | O9: FALSE
A10: BR-007-CP | B10: Alex Kidd in Miracle World | E10: 1986 | G10: CP | H10: Action | I10: Platform | O10: FALSE
A11: BR-007-GG | B11: Alex Kidd in Miracle World | E11: 1986 | G11: GG | H11: Action | I11: Platform | O11: FALSE | P11: [Verificar ano da edição]
A12: BR-008-CP | B12: Alex Kidd In Shinobi World | E12: 1990 | G12: CP | H12: Action | I12: Platform | O12: FALSE
A13: BR-008-GG | B13: Alex Kidd In Shinobi World | E13: 1990 | G13: GG | H13: Action | I13: Platform | O13: FALSE | P13: [Verificar ano da edição]
A14: BR-009-CP | B14: Alex Kidd: The Lost Stars | E14: 1988 | G14: CP | H14: Action | O14: TRUE
A15: BR-010-GG | B15: Alien 3 | E15: 1992 | G15: GG | H15: Action | O15: FALSE
A16: BR-011-GG | B16: Alien Storm | E16: 1991 | G16: GG | H16: Action | O16: FALSE
A17: BR-012-GG | B17: Alien Syndrome | E17: 1987 | G17: GG | H17: Action | O17: TRUE
A18: BR-013-AZ | B18: Altered Beast | E18: 1989 | G18: AZ | H18: Action | O18: TRUE | P18: [Verificar ano da edição]
A19: BR-013-CP | B19: Altered Beast | E19: 1989 | G19: CP | H19: Action | O19: TRUE
A20: BR-013-GG | B20: Altered Beast | E20: 1989 | G20: GG | H20: Action | O20: TRUE | P20: [Verificar ano da edição]
A21: BR-014-GG | B21: American Baseball | E21: 1989 | G21: GG | H21: Sport | O21: FALSE
A22: BR-015-AB | B22: Andre Agassi Tennis | E22: 1993 | G22: AB | H22: Sport | O22: FALSE
A23: BR-016-AZ | B23: Ariel The Little Mermaid | E23: 1996 | G23: AZ | H23: Action | O23: FALSE
A24: BR-017-AZ | B24: As Aventuras da TV Colosso | E24: 1996 | G24: AZ | H24: Action | O24: FALSE
A25: BR-018-CP | B25: Assault City | E25: 1990 | G25: CP | H25: Action | O25: FALSE
A26: BR-019-GG | B26: Asterix | E26: 1991 | G26: GG | H26: Action | O26: FALSE
A27: BR-020-AB | B27: Asterix and the Great Rescue | E27: 1994 | G27: AB | H27: Action | O27: FALSE
A28: BR-021-AB | B28: Astérix and the Secret Mission | E28: 1994 | G28: AB | H28: Action | O28: FALSE
A29: BR-022-CP | B29: Astro Warrior | E29: 1986 | G29: CP | H29: Action | O29: FALSE
A30: BR-022-GG | B30: Astro Warrior | E30: 1986 | G30: GG | H30: Action | O30: FALSE | P30: [Verificar ano da edição]
A31: BR-023-GG | B31: Ayrton Senna's Super Monaco GP II | E31: 1992 | G31: GG | H31: Racing | O31: FALSE
A32: BR-024-CP | B32: Aztec Adventure | E32: 1987 | G32: CP | H32: Action | O32: TRUE
A33: BR-025-GG | B33: Back to the Future II | E33: 1991 | G33: GG | H33: Action | O33: FALSE
A34: BR-026-AZ | B34: Baku Baku | E34: 1996 | G34: AZ | H34: Action | O34: FALSE
A35: BR-027-GG | B35: Bank Panic | E35: 1987 | G35: GG | H35: Action | O35: FALSE
A36: BR-028-GG | B36: Basketball Nightmare | E36: 1989 | G36: GG | H36: Sport | O36: FALSE
A37: BR-029-GP | B37: Batman Returns | E37: 1993 | G37: GP | H37: Action | O37: FALSE
A38: BR-030-CP | B38: Battle OutRun | E38: 1989 | G38: CP | H38: Racing | O38: TRUE
A39: BR-031-AZ | B39: Battlemaniacs | E39: 1996 | G39: AZ | H39: Action | O39: FALSE
A40: BR-032-CP | B40: Black Belt | E40: 1986 | G40: CP | H40: Action | O40: FALSE
...

Sheet Minha_Colecao
J1: ="🎮 Tectoy: " & AA3 & " | 📦 Total: " & AA4 & " | 📦 CIB: " & AA5 & " • 📻 Boxed: " & AA6 & " • 🕹️ Loose: " & AA7 & " | CP: " & AA8 & " • GG: " & AA9 & " • GP: " & AA10 & " • AB: " & AA11 & " • AZ: " & AA12 -> 🎮 Tectoy: 132/245 | 📦 Total: 157 | 📦 CIB: 73 • 📻 Boxed: 26 • 🕹️ Loose: 54 | CP: 40/62 • GG: 68/102 • GP: 13/15 • AB: 11/56 • AZ: 4/35
A2: id | B2: exemplar | C2: Titulo_br | D2: Titulo_int | E2: Status | F2: Edicao | G2: Prioridade | H2: My_rate | I2: Ano | J2: Regiao | K2: Catalogo | L2: Raridade | M2: Cartucho | N2: Estojo | O2: Encarte | P2: Manual | Q2: Serial Bat. | R2: Lote | S2: Data_compra | T2: valor individual | U2: Observacao
D3: Trivial Pursuit - Genus Edition | E3: =IF(A3="","",IF(M3=FALSE,"Não possuo",IF(AND(M3,N3,O3,P3),"CIB",IF(AND(M3,N3,O3,NOT(P3)),"Boxed",IF(AND(M3,NOT(N3),NOT(O3),NOT(P3)),"Loose","Incompleto"))))) | G3: 0 | J3: EU | K3: EU | M3: TRUE | N3: FALSE | O3: FALSE | P3: FALSE | Q3: n/s | Z3: tectoy | AA3: =IFERROR(__xludf.DUMMYFUNCTION("COUNTUNIQUE(ARRAYFORMULA(IF((K3:K296=""TecToy"")*(E3:E296<>""Não possuo"")*(A3:A296<>""""), REGEXEXTRACT(A3:A296, ""-(\d+)-""), """"))) & ""/"" & COUNTUNIQUE(ARRAYFORMULA(IF(Catalogo_BR!A2:A296<>"""", REGEXEXTRACT(Catalogo_BR!A2:A296, ""-(\d+)-""), """"))"&")"),"132/245") -> 132/245
D4: Speedball | E4: =IF(A4="","",IF(M4=FALSE,"Não possuo",IF(AND(M4,N4,O4,P4),"CIB",IF(AND(M4,N4,O4,NOT(P4)),"Boxed",IF(AND(M4,NOT(N4),NOT(O4),NOT(P4)),"Loose","Incompleto"))))) | G4: 0 | J4: EU | K4: EU | M4: TRUE | N4: FALSE | O4: FALSE | P4: FALSE | Q4: n/s | Z4: total | AA4: =COUNTIFS(E3:E296, "<>Não possuo", E3:E296, "<>") - IFERROR(COUNTIFS(E3:E296, "<>Não possuo", C3:C296, "", D3:D296, ""), 0) -> 157
D5: Bomber Raid | E5: =IF(A5="","",IF(M5=FALSE,"Não possuo",IF(AND(M5,N5,O5,P5),"CIB",IF(AND(M5,N5,O5,NOT(P5)),"Boxed",IF(AND(M5,NOT(N5),NOT(O5),NOT(P5)),"Loose","Incompleto"))))) | G5: 0 | J5: EU | K5: EU | M5: TRUE | N5: FALSE | O5: FALSE | P5: FALSE | Q5: n/s | Z5: cib | AA5: =COUNTIF(E3:E296, "CIB") -> 73
A6: BR-077-GG | C6: {=IF(A6="","",_xlfn.XLOOKUP(A6,Catalogo_BR!$A$2:$A$277,Catalogo_BR!$B$2:$B$277,"",0))} -> Gain Ground | E6: =IF(A6="","",IF(M6=FALSE,"Não possuo",IF(AND(M6,N6,O6,P6),"CIB",IF(AND(M6,N6,O6,NOT(P6)),"Boxed",IF(AND(M6,NOT(N6),NOT(O6),NOT(P6)),"Loose","Incompleto"))))) -> Boxed | F6: GG | G6: 0 | H6: 4 | I6: 1991 | J6: BR | K6: Tectoy | L6: Raro | M6: TRUE | N6: TRUE | O6: TRUE | P6: FALSE | Q6: n/s | Z6: boxed | AA6: =COUNTIF(E3:E296, "Boxed") -> 26
A7: BR-096-GG | C7: {=IF(A7="","",_xlfn.XLOOKUP(A7,Catalogo_BR!$A$2:$A$277,Catalogo_BR!$B$2:$B$277,"",0))} -> Golvellius | E7: =IF(A7="","",IF(M7=FALSE,"Não possuo",IF(AND(M7,N7,O7,P7),"CIB",IF(AND(M7,N7,O7,NOT(P7)),"Boxed",IF(AND(M7,NOT(N7),NOT(O7),NOT(P7)),"Loose","Incompleto"))))) -> Boxed | F7: GG | G7: 0 | H7: 5 | I7: 1988 | J7: BR | K7: Tectoy | L7: Raro | M7: TRUE | N7: TRUE | O7: TRUE | P7: FALSE | Q7: n/s | Z7: loose | AA7: =COUNTIF(E3:E296, "Loose") -> 54
A8: BR-168-GG | C8: {=IF(A8="","",_xlfn.XLOOKUP(A8,Catalogo_BR!$A$2:$A$277,Catalogo_BR!$B$2:$B$277,"",0))} -> Sagaia | E8: =IF(A8="","",IF(M8=FALSE,"Não possuo",IF(AND(M8,N8,O8,P8),"CIB",IF(AND(M8,N8,O8,NOT(P8)),"Boxed",IF(AND(M8,NOT(N8),NOT(O8),NOT(P8)),"Loose","Incompleto"))))) -> Boxed | F8: GG | G8: 0 | H8: 4 | I8: 1992 | J8: BR | K8: Tectoy | L8: Raro | M8: TRUE | N8: TRUE | O8: TRUE | P8: FALSE | Q8: n/s | Z8: cp | AA8: =IFERROR(__xludf.DUMMYFUNCTION("COUNTUNIQUE(FILTER(A3:A296, F3:F296=""CP"", E3:E296<>""Não possuo"", A3:A296<>"""")) & ""/"" & COUNTUNIQUE(FILTER(Catalogo_BR!A2:A296, Catalogo_BR!G2:G296=""CP"", Catalogo_BR!A2:A296<>""""))"),"40/62") -> 40/62
A9: BR-152-GG | C9: {=IF(A9="","",_xlfn.XLOOKUP(A9,Catalogo_BR!$A$2:$A$277,Catalogo_BR!$B$2:$B$277,"",0))} -> Psychic World | E9: =IF(A9="","",IF(M9=FALSE,"Não possuo",IF(AND(M9,N9,O9,P9),"CIB",IF(AND(M9,N9,O9,NOT(P9)),"Boxed",IF(AND(M9,NOT(N9),NOT(O9),NOT(P9)),"Loose","Incompleto"))))) -> Boxed | F9: GG | G9: 0 | H9: 5 | I9: 1991 | J9: BR | K9: Tectoy | L9: Raro | M9: TRUE | N9: TRUE | O9: TRUE | P9: FALSE | Q9: n/s | Z9: gg | AA9: =IFERROR(__xludf.DUMMYFUNCTION("COUNTUNIQUE(FILTER(A3:A296, F3:F296=""GG"", E3:E296<>""Não possuo"", A3:A296<>"""")) & ""/"" & COUNTUNIQUE(FILTER(Catalogo_BR!A2:A296, Catalogo_BR!G2:G296=""GG"", Catalogo_BR!A2:A296<>""""))"),"68/102") -> 68/102
A10: BR-241-GG | C10: {=IF(A10="","",_xlfn.XLOOKUP(A10,Catalogo_BR!$A$2:$A$277,Catalogo_BR!$B$2:$B$277,"",0))} -> Y's | E10: =IF(A10="","",IF(M10=FALSE,"Não possuo",IF(AND(M10,N10,O10,P10),"CIB",IF(AND(M10,N10,O10,NOT(P10)),"Boxed",IF(AND(M10,NOT(N10),NOT(O10),NOT(P10)),"Loose","Incompleto"))))) -> Boxed | F10: GG | G10: 0 | H10: 5 | I10: 1988 | J10: BR | K10: Tectoy | L10: Raro | M10: TRUE | N10: TRUE | O10: TRUE | P10: FALSE | Q10: n/s | Z10: gp | AA10: =IFERROR(__xludf.DUMMYFUNCTION("COUNTUNIQUE(FILTER(A3:A296, F3:F296=""GP"", E3:E296<>""Não possuo"", A3:A296<>"""")) & ""/"" & COUNTUNIQUE(FILTER(Catalogo_BR!A2:A296, Catalogo_BR!G2:G296=""GP"", Catalogo_BR!A2:A296<>""""))"),"13/15") -> 13/15
A11: BR-217-GG | C11: {=IF(A11="","",_xlfn.XLOOKUP(A11,Catalogo_BR!$A$2:$A$277,Catalogo_BR!$B$2:$B$277,"",0))} -> The Simpsons: Bart vs. The Space Mutants | E11: =IF(A11="","",IF(M11=FALSE,"Não possuo",IF(AND(M11,N11,O11,P11),"CIB",IF(AND(M11,N11,O11,NOT(P11)),"Boxed",IF(AND(M11,NOT(N11),NOT(O11),NOT(P11)),"Loose","Incompleto"))))) -> Boxed | F11: GG | G11: 0 | H11: 3 | I11: 1992 | J11: BR | K11: Tectoy | L11: Raro | M11: TRUE | N11: TRUE | O11: TRUE | P11: FALSE | Q11: n/s | Z11: ab | AA11: =IFERROR(__xludf.DUMMYFUNCTION("COUNTUNIQUE(FILTER(A3:A296, F3:F296=""AB"", E3:E296<>""Não possuo"", A3:A296<>"""")) & ""/"" & COUNTUNIQUE(FILTER(Catalogo_BR!A2:A296, Catalogo_BR!G2:G296=""AB"", Catalogo_BR!A2:A296<>""""))"),"11/56") -> 11/56
A12: BR-160-GG | C12: {=IF(A12="","",_xlfn.XLOOKUP(A12,Catalogo_BR!$A$2:$A$277,Catalogo_BR!$B$2:$B$277,"",0))} -> Rastan | E12: =IF(A12="","",IF(M12=FALSE,"Não possuo",IF(AND(M12,N12,O12,P12),"CIB",IF(AND(M12,N12,O12,NOT(P12)),"Boxed",IF(AND(M12,NOT(N12),NOT(O12),NOT(P12)),"Loose","Incompleto"))))) -> Boxed | F12: GG | G12: 1 | H12: 4 | I12: 1989 | J12: EUA | K12: Tectoy | L12: Raro | M12: TRUE | N12: TRUE | O12: TRUE | P12: FALSE | Q12: n/s | Z12: az | AA12: =IFERROR(__xludf.DUMMYFUNCTION("COUNTUNIQUE(FILTER(A3:A296, F3:F296=""AZ"", E3:E296<>""Não possuo"", A3:A296<>"""")) & ""/"" & COUNTUNIQUE(FILTER(Catalogo_BR!A2:A296, Catalogo_BR!G2:G296=""AZ"", Catalogo_BR!A2:A296<>""""))"),"4/35") -> 4/35
A13: BR-127-GG | C13: {=IF(A13="","",_xlfn.XLOOKUP(A13,Catalogo_BR!$A$2:$A$277,Catalogo_BR!$B$2:$B$277,"",0))} -> Miracle Warriors | E13: =IF(A13="","",IF(M13=FALSE,"Não possuo",IF(AND(M13,N13,O13,P13),"CIB",IF(AND(M13,N13,O13,NOT(P13)),"Boxed",IF(AND(M13,NOT(N13),NOT(O13),NOT(P13)),"Loose","Incompleto"))))) -> Boxed | F13: GG | G13: 3 | H13: 5 | I13: 1987 | J13: BR | K13: Tectoy | L13: Raro | M13: TRUE | N13: TRUE | O13: TRUE | P13: FALSE | Q13: n/s
A14: BR-027-GG | C14: {=IF(A14="","",_xlfn.XLOOKUP(A14,Catalogo_BR!$A$2:$A$277,Catalogo_BR!$B$2:$B$277,"",0))} -> Bank Panic | E14: =IF(A14="","",IF(M14=FALSE,"Não possuo",IF(AND(M14,N14,O14,P14),"CIB",IF(AND(M14,N14,O14,NOT(P14)),"Boxed",IF(AND(M14,NOT(N14),NOT(O14),NOT(P14)),"Loose","Incompleto"))))) -> CIB | F14: GG | G14: 0 | H14: 3 | I14: 1987 | J14: BR | K14: Tectoy | L14: Raro | M14: TRUE | N14: TRUE | O14: TRUE | P14: TRUE | Q14: n/s
A15: BR-050-GG | C15: {=IF(A15="","",_xlfn.XLOOKUP(A15,Catalogo_BR!$A$2:$A$277,Catalogo_BR!$B$2:$B$277,"",0))} -> Danan | E15: =IF(A15="","",IF(M15=FALSE,"Não possuo",IF(AND(M15,N15,O15,P15),"CIB",IF(AND(M15,N15,O15,NOT(P15)),"Boxed",IF(AND(M15,NOT(N15),NOT(O15),NOT(P15)),"Loose","Incompleto"))))) -> CIB | F15: GG | G15: 0 | H15: 4 | I15: 1991 | J15: BR | K15: Tectoy | L15: Raro | M15: TRUE | N15: TRUE | O15: TRUE | P15: TRUE | Q15: n/s
A16: BR-172-GG | C16: {=IF(A16="","",_xlfn.XLOOKUP(A16,Catalogo_BR!$A$2:$A$277,Catalogo_BR!$B$2:$B$277,"",0))} -> Scramble Spirits | E16: =IF(A16="","",IF(M16=FALSE,"Não possuo",IF(AND(M16,N16,O16,P16),"CIB",IF(AND(M16,N16,O16,NOT(P16)),"Boxed",IF(AND(M16,NOT(N16),NOT(O16),NOT(P16)),"Loose","Incompleto"))))) -> CIB | F16: GG | G16: 0 | H16: 3 | I16: 1989 | J16: BR | K16: Tectoy | L16: Raro | M16: TRUE | N16: TRUE | O16: TRUE | P16: TRUE | Q16: n/s
A17: BR-135-GG | C17: {=IF(A17="","",_xlfn.XLOOKUP(A17,Catalogo_BR!$A$2:$A$277,Catalogo_BR!$B$2:$B$277,"",0))} -> Ninja Gaiden | E17: =IF(A17="","",IF(M17=FALSE,"Não possuo",IF(AND(M17,N17,O17,P17),"CIB",IF(AND(M17,N17,O17,NOT(P17)),"Boxed",IF(AND(M17,NOT(N17),NOT(O17),NOT(P17)),"Loose","Incompleto"))))) -> CIB | F17: GG | G17: 0 | H17: 5 | I17: 1992 | J17: BR | K17: Tectoy | L17: Raro | M17: TRUE | N17: TRUE | O17: TRUE | P17: TRUE | Q17: n/s
A18: BR-143-GG | C18: {=IF(A18="","",_xlfn.XLOOKUP(A18,Catalogo_BR!$A$2:$A$277,Catalogo_BR!$B$2:$B$277,"",0))} -> Phantasy Star | E18: =IF(A18="","",IF(M18=FALSE,"Não possuo",IF(AND(M18,N18,O18,P18),"CIB",IF(AND(M18,N18,O18,NOT(P18)),"Boxed",IF(AND(M18,NOT(N18),NOT(O18),NOT(P18)),"Loose","Incompleto"))))) -> CIB | F18: GG | G18: 0 | H18: 5 | I18: 1987 | J18: BR | K18: Tectoy | L18: Raro | M18: TRUE | N18: TRUE | O18: TRUE | P18: TRUE | Q18: n/s
A19: BR-028-GG | C19: {=IF(A19="","",_xlfn.XLOOKUP(A19,Catalogo_BR!$A$2:$A$277,Catalogo_BR!$B$2:$B$277,"",0))} -> Basketball Nightmare | E19: =IF(A19="","",IF(M19=FALSE,"Não possuo",IF(AND(M19,N19,O19,P19),"CIB",IF(AND(M19,N19,O19,NOT(P19)),"Boxed",IF(AND(M19,NOT(N19),NOT(O19),NOT(P19)),"Loose","Incompleto"))))) -> CIB | F19: GG | G19: 0 | H19: 4 | I19: 1989 | J19: BR | K19: Tectoy | L19: Raro | M19: TRUE | N19: TRUE | O19: TRUE | P19: TRUE | Q19: n/s
A20: BR-054-GG | C20: {=IF(A20="","",_xlfn.XLOOKUP(A20,Catalogo_BR!$A$2:$A$277,Catalogo_BR!$B$2:$B$277,"",0))} -> Dick Tracy | E20: =IF(A20="","",IF(M20=FALSE,"Não possuo",IF(AND(M20,N20,O20,P20),"CIB",IF(AND(M20,N20,O20,NOT(P20)),"Boxed",IF(AND(M20,NOT(N20),NOT(O20),NOT(P20)),"Loose","Incompleto"))))) -> CIB | F20: GG | G20: 0 | H20: 3 | I20: 1991 | J20: BR | K20: Tectoy | L20: Raro | M20: TRUE | N20: TRUE | O20: TRUE | P20: TRUE | Q20: n/s
A21: BR-045-CP | C21: {=IF(A21="","",_xlfn.XLOOKUP(A21,Catalogo_BR!$A$2:$A$277,Catalogo_BR!$B$2:$B$277,"",0))} -> Cloud Master | E21: =IF(A21="","",IF(M21=FALSE,"Não possuo",IF(AND(M21,N21,O21,P21),"CIB",IF(AND(M21,N21,O21,NOT(P21)),"Boxed",IF(AND(M21,NOT(N21),NOT(O21),NOT(P21)),"Loose","Incompleto"))))) -> CIB | F21: CP | G21: 0 | H21: 4 | I21: 1989 | J21: BR | K21: Tectoy | L21: Raro | M21: TRUE | N21: TRUE | O21: TRUE | P21: TRUE | Q21: n/s
A22: BR-192-AZ | C22: {=IF(A22="","",_xlfn.XLOOKUP(A22,Catalogo_BR!$A$2:$A$277,Catalogo_BR!$B$2:$B$277,"",0))} -> Street Fighter II | E22: =IF(A22="","",IF(M22=FALSE,"Não possuo",IF(AND(M22,N22,O22,P22),"CIB",IF(AND(M22,N22,O22,NOT(P22)),"Boxed",IF(AND(M22,NOT(N22),NOT(O22),NOT(P22)),"Loose","Incompleto"))))) -> CIB | F22: AZ | G22: 0 | H22: 3 | I22: 1997 | J22: BR | K22: Tectoy | L22: Raro | M22: TRUE | N22: TRUE | O22: TRUE | P22: TRUE | Q22: n/s
A23: BR-240-AZ | C23: {=IF(A23="","",_xlfn.XLOOKUP(A23,Catalogo_BR!$A$2:$A$277,Catalogo_BR!$B$2:$B$277,"",0))} -> X-Men Mojo World | E23: =IF(A23="","",IF(M23=FALSE,"Não possuo",IF(AND(M23,N23,O23,P23),"CIB",IF(AND(M23,N23,O23,NOT(P23)),"Boxed",IF(AND(M23,NOT(N23),NOT(O23),NOT(P23)),"Loose","Incompleto"))))) -> CIB | F23: AZ | G23: 0 | H23: 3 | I23: 1996 | J23: BR | K23: Tectoy | L23: Raro | M23: TRUE | N23: TRUE | O23: TRUE | P23: TRUE | Q23: n/s
A24: BR-007-GG | C24: {=IF(A24="","",_xlfn.XLOOKUP(A24,Catalogo_BR!$A$2:$A$277,Catalogo_BR!$B$2:$B$277,"",0))} -> Alex Kidd in Miracle World | E24: =IF(A24="","",IF(M24=FALSE,"Não possuo",IF(AND(M24,N24,O24,P24),"CIB",IF(AND(M24,N24,O24,NOT(P24)),"Boxed",IF(AND(M24,NOT(N24),NOT(O24),NOT(P24)),"Loose","Incompleto"))))) -> Não possuo | F24: GG | G24: 1 | H24: 5 | I24: 1986 | J24: BR | K24: Tectoy | L24: Raro | M24: FALSE | N24: FALSE | O24: FALSE | P24: FALSE | Q24: n/s
... A33: BR-122-AB | C33: {=IF(A33="","",_xlfn.XLOOKUP(A33,Catalogo_BR!$A$2:$A$277,Catalogo_BR!$B$2:$B$277,"",0))} -> Masters of Combat | E33: =IF(A33="","",IF(M33=FALSE,"Não possuo",IF(AND(M33,N33,O33,P33),"CIB",IF(AND(M33,N33,O33,NOT(P33)),"Boxed",IF(AND(M33,NOT(N33),NOT(O33),NOT(P33)),"Loose","Incompleto"))))) -> Não possuo | F33: AB | G33: 3 | H33: 3 | I33: 1993 | J33: BR | K33: Tectoy | L33: Raro | M33: FALSE | N33: FALSE | O33: FALSE | P33: FALSE | Q33: n/s
A34: BR-143-AZ | C34: {=IF(A34="","",_xlfn.XLOOKUP(A34,Catalogo_BR!$A$2:$A$277,Catalogo_BR!$B$2:$B$277,"",0))} -> Phantasy Star | E34: =IF(A34="","",IF(M34=FALSE,"Não possuo",IF(AND(M34,N34,O34,P34),"CIB",IF(AND(M34,N34,O34,NOT(P34)),"Boxed",IF(AND(M34,NOT(N34),NOT(O34),NOT(P34)),"Loose","Incompleto"))))) -> Não possuo | F34: AZ | G34: 3 | H34: 5 | I34: 1987 | J34: BR | K34: Tectoy | L34: Raro | M34: FALSE | N34: FALSE | O34: FALSE | P34: FALSE | Q34: n/s | U34: [CONFIRME: qual edição você realmente possui? Posse migrada automaticamente para esta linha]
A35: BR-163-AB | C35: {=IF(A35="","",_xlfn.XLOOKUP(A35,Catalogo_BR!$A$2:$A$277,Catalogo_BR!$B$2:$B$277,"",0))} -> Road Rash | E35: =IF(A35="","",IF(M35=FALSE,"Não possuo",IF(AND(M35,N35,O35,P35),"CIB",IF(AND(M35,N35,O35,NOT(P35)),"Boxed",IF(AND(M35,NOT(N35),NOT(O35),NOT(P35)),"Loose","Incompleto"))))) -> Não possuo | F35: AB | G35: 3 | H35: 3 | I35: 1994 | J35: BR | K35: Tectoy | L35: Raro | M35: FALSE | N35: FALSE | O35: FALSE | P35: FALSE | Q35: n/s
A36: BR-179-AZ | C36: {=IF(A36="","",_xlfn.XLOOKUP(A36,Catalogo_BR!$A$2:$A$277,Catalogo_BR!$B$2:$B$277,"",0))} -> Sítio do Picapau Amarelo | E36: =IF(A36="","",IF(M36=FALSE,"Não possuo",IF(AND(M36,N36,O36,P36),"CIB",IF(AND(M36,N36,O36,NOT(P36)),"Boxed",IF(AND(M36,NOT(N36),NOT(O36),NOT(P36)),"Loose","Incompleto"))))) -> Não possuo | F36: AZ | G36: 3 | H36: 1 | I36: 1998 | J36: BR | K36: Tectoy | L36: Raro | M36: FALSE | N36: FALSE | O36: FALSE | P36: FALSE | Q36: n/s
A37: BR-228-AZ | C37: {=IF(A37="","",_xlfn.XLOOKUP(A37,Catalogo_BR!$A$2:$A$277,Catalogo_BR!$B$2:$B$277,"",0))} -> Virtua Fighter Animation | E37: =IF(A37="","",IF(M37=FALSE,"Não possuo",IF(AND(M37,N37,O37,P37),"CIB",IF(AND(M37,N37,O37,NOT(P37)),"Boxed",IF(AND(M37,NOT(N37),NOT(O37),NOT(P37)),"Loose","Incompleto"))))) -> Não possuo | F37: AZ | G37: 3 | H37: 2 | I37: 1997 | J37: BR | K37: Tectoy | L37: Raro | M37: FALSE | N37: FALSE | O37: FALSE | P37: FALSE | Q37: n/s
A38: BR-181-AZ | C38: {=IF(A38="","",_xlfn.XLOOKUP(A38,Catalogo_BR!$A$2:$A$277,Catalogo_BR!$B$2:$B$277,"",0))} -> Sonic Blast | E38: =IF(A38="","",IF(M38=FALSE,"Não possuo",IF(AND(M38,N38,O38,P38),"CIB",IF(AND(M38,N38,O38,NOT(P38)),"Boxed",IF(AND(M38,NOT(N38),NOT(O38),NOT(P38)),"Loose","Incompleto"))))) -> Boxed | F38: AZ | G38: 0 | H38: 3 | I38: 1997 | J38: BR | K38: Tectoy | L38: Muito raro | M38: TRUE | N38: TRUE | O38: TRUE | P38: FALSE | Q38: n/s
A39: BR-103-GG | C39: {=IF(A39="","",_xlfn.XLOOKUP(A39,Catalogo_BR!$A$2:$A$277,Catalogo_BR!$B$2:$B$277,"",0))} -> Impossible Mission | E39: =IF(A39="","",IF(M39=FALSE,"Não possuo",IF(AND(M39,N39,O39,P39),"CIB",IF(AND(M39,N39,O39,NOT(P39)),"Boxed",IF(AND(M39,NOT(N39),NOT(O39),NOT(P39)),"Loose","Incompleto"))))) -> Boxed | F39: GG | G39: 0 | H39: 3 | I39: 1990 | J39: BR | K39: Tectoy | L39: Muito raro | M39: TRUE | N39: TRUE | O39: TRUE | P39: FALSE | Q39: n/s
A40: BR-147-GG | C40: {=IF(A40="","",_xlfn.XLOOKUP(A40,Catalogo_BR!$A$2:$A$277,Catalogo_BR!$B$2:$B$277,"",0))} -> Power Strike | E40: =IF(A40="","",IF(M40=FALSE,"Não possuo",IF(AND(M40,N40,O40,P40),"CIB",IF(AND(M40,N40,O40,NOT(P40)),"Boxed",IF(AND(M40,NOT(N40),NOT(O40),NOT(P40)),"Loose","Incompleto"))))) -> Boxed | F40: GG | G40: 0 | H40: 4 | I40: 1988 | J40: BR | K40: Tectoy | L40: Muito raro | M40: TRUE | N40: TRUE | O40: TRUE | P40: FALSE | Q40: n/s
A41: BR-003-GG | C41: {=IF(A41="","",_xlfn.XLOOKUP(A41,Catalogo_BR!$A$2:$A$277,Catalogo_BR!$B$2:$B$277,"",0))} -> Aerial Assault | E41: =IF(A41="","",IF(M41=FALSE,"Não possuo",IF(AND(M41,N41,O41,P41),"CIB",IF(AND(M41,N41,O41,NOT(P41)),"Boxed",IF(AND(M41,NOT(N41),NOT(O41),NOT(P41)),"Loose","Incompleto"))))) -> CIB | F41: GG | G41: 0 | H41: 4 | I41: 1990 | J41: BR | K41: Tectoy | L41: Muito raro | M41: TRUE | N41: TRUE | O41: TRUE | P41: TRUE | Q41: n/s
A42: BR-002-GG | C42: {=IF(A42="","",_xlfn.XLOOKUP(A42,Catalogo_BR!$A$2:$A$277,Catalogo_BR!$B$2:$B$277,"",0))} -> Action Fighter | E42: =IF(A42="","",IF(M42=FALSE,"Não possuo",IF(AND(M42,N42,O42,P42),"CIB",IF(AND(M42,N42,O42,NOT(P42)),"Boxed",IF(AND(M42,NOT(N42),NOT(O42),NOT(P42)),"Loose","Incompleto"))))) -> CIB | F42: GG | G42: 0 | H42: 4 | I42: 1986 | J42: BR | K42: Tectoy | L42: Muito raro | M42: TRUE | N42: TRUE | O42: TRUE | P42: TRUE | Q42: n/s
A43: BR-094-GG | C43: {=IF(A43="","",_xlfn.XLOOKUP(A43,Catalogo_BR!$A$2:$A$277,Catalogo_BR!$B$2:$B$277,"",0))} -> Golden Axe Warrior | E43: =IF(A43="","",IF(M43=FALSE,"Não possuo",IF(AND(M43,N43,O43,P43),"CIB",IF(AND(M43,N43,O43,NOT(P43)),"Boxed",IF(AND(M43,NOT(N43),NOT(O43),NOT(P43)),"Loose","Incompleto"))))) -> CIB | F43: GG | G43: 0 | H43: 5 | I43: 1991 | J43: BR | K43: Tectoy | L43: Muito raro | M43: TRUE | N43: TRUE | O43: TRUE | P43: TRUE | Q43: n/s
A44: BR-012-GG | C44: {=IF(A44="","",_xlfn.XLOOKUP(A44,Catalogo_BR!$A$2:$A$277,Catalogo_BR!$B$2:$B$277,"",0))} -> Alien Syndrome | E44: =IF(A44="","",IF(M44=FALSE,"Não possuo",IF(AND(M44,N44,O44,P44),"CIB",IF(AND(M44,N44,O44,NOT(P44)),"Boxed",IF(AND(M44,NOT(N44),NOT(O44),NOT(P44)),"Loose","Incompleto"))))) -> CIB | F44: GG | G44: 1 | H44: 3 | I44: 1987 | J44: EU | K44: Tectoy | L44: Muito raro | M44: TRUE | N44: TRUE | O44: TRUE | P44: TRUE | Q44: n/s
A45: BR-187-GG | C45: {=IF(A45="","",_xlfn.XLOOKUP(A45,Catalogo_BR!$A$2:$A$277,Catalogo_BR!$B$2:$B$277,"",0))} -> SpellCaster | E45: =IF(A45="","",IF(M45=FALSE,"Não possuo",IF(AND(M45,N45,O45,P45),"CIB",IF(AND(M45,N45,O45,NOT(P45)),"Boxed",IF(AND(M45,NOT(N45),NOT(O45),NOT(P45)),"Loose","Incompleto"))))) -> CIB | F45: GG | G45: 0 | H45: 5 | I45: 1988 | J45: BR | K45: Tectoy | L45: Muito raro | M45: TRUE | N45: TRUE | O45: TRUE | P45: TRUE | Q45: n/s
A46: BR-012-GG | C46: {=IF(A46="","",_xlfn.XLOOKUP(A46,Catalogo_BR!$A$2:$A$277,Catalogo_BR!$B$2:$B$277,"",0))} -> Alien Syndrome | E46: =IF(A46="","",IF(M46=FALSE,"Não possuo",IF(AND(M46,N46,O46,P46),"CIB",IF(AND(M46,N46,O46,NOT(P46)),"Boxed",IF(AND(M46,NOT(N46),NOT(O46),NOT(P46)),"Loose","Incompleto"))))) -> Loose | F46: GG | G46: 0 | H46: 3 | I46: 1987 | J46: EU | K46: Tectoy | L46: Muito raro | M46: TRUE | N46: FALSE | O46: FALSE | P46: FALSE | Q46: n/s
... A48: BR-011-GG | C48: {=IF(A48="","",_xlfn.XLOOKUP(A48,Catalogo_BR!$A$2:$A$277,Catalogo_BR!$B$2:$B$277,"",0))} -> Alien Storm | E48: =IF(A48="","",IF(M48=FALSE,"Não possuo",IF(AND(M48,N48,O48,P48),"CIB",IF(AND(M48,N48,O48,NOT(P48)),"Boxed",IF(AND(M48,NOT(N48),NOT(O48),NOT(P48)),"Loose","Incompleto"))))) -> Não possuo | F48: GG | G48: 1 | H48: 3 | I48: 1991 | J48: BR | K48: Tectoy | L48: Incomum | M48: FALSE | N48: FALSE | O48: FALSE | P48: FALSE | Q48: n/s
A49: BR-116-AZ | C49: {=IF(A49="","",_xlfn.XLOOKUP(A49,Catalogo_BR!$A$2:$A$277,Catalogo_BR!$B$2:$B$277,"",0))} -> Legend of Illusion starring Mickey Mouse | E49: =IF(A49="","",IF(M49=FALSE,"Não possuo",IF(AND(M49,N49,O49,P49),"CIB",IF(AND(M49,N49,O49,NOT(P49)),"Boxed",IF(AND(M49,NOT(N49),NOT(O49),NOT(P49)),"Loose","Incompleto"))))) -> Não possuo | F49: AZ | G49: 3 | H49: 3 | I49: 1998 | J49: BR | K49: Tectoy | L49: Muito raro | M49: FALSE | N49: FALSE | O49: FALSE | P49: FALSE | Q49: n/s | U49: [CORRIGIDO: BR-116B não possui variante correspondente no catálogo atual]
...
